Workbook

Sheet Players
A1: Player | B1: Division | C1: Display Name (optional)
A2: Player A | B2: A
A3: Player B | B3: A
A4: Player C | B4: A
A5: Player D | B5: A
A6: Player E | B6: A
A7: Player F | B7: B
A8: Player G | B8: B
A9: Player H | B9: B
A10: Player I | B10: B
A11: Player J | B11: B

Sheet Settings
A1: Setting | B1: Value
A2: Total base points per match | B2: 10
A3: Win bonus points | B3: 1
A4: Tie bonus points | B4: 0
A5: Total scheduled matches | B5: 22
A6: Update title prefix | B6: Indoor Sim Golf League Update –
A7: After Round label (edit) | B7: After Round X

Sheet Matches
A1: Date | B1: Division | C1: Player 1 | D1: Player 2 | E1: P1 Base Pts | F1: P2 Base Pts | G1: Winner | H1: P1 Bonus | I1: P2 Bonus | J1: P1 Total | K1: P2 Total | L1: Notes | M1: Completed? | N1: P1_W | O1: P1_L | P1: P1_T | Q1: P2_W | R1: P2_L | S1: P2_T | T1: Result
G2: =IF(OR(E2="",F2=""),"",IF(E2>F2,C2,IF(E2<F2,D2,"TIE"))) | H2: =IF(G2="", "", IF(G2=C2,Settings!$B$3,0)) | I2: =IF(G2="", "", IF(G2=D2,Settings!$B$3,0)) | J2: =IF(OR(E2="",H2=""),"",E2+H2) | K2: =IF(OR(F2="",I2=""),"",F2+I2) | M2: =IF(AND(A2<>"",B2<>"",C2<>"",D2<>"",E2<>"",F2<>""),1,0) | N2: =IF(M2=0,"",IF(E2>F2,1,0)) | O2: =IF(M2=0,"",IF(E2<F2,1,0)) | P2: =IF(M2=0,"",IF(E2=F2,1,0)) | Q2: =IF(M2=0,"",IF(F2>E2,1,0)) | R2: =IF(M2=0,"",IF(F2<E2,1,0)) | S2: =IF(M2=0,"",IF(F2=E2,1,0)) | T2: =IF(M2=0,"",IF(E2>F2,C2&" def. "&D2,IF(E2<F2,D2&" def. "&C2,C2&" tied "&D2))&" "&TEXT(E2,"0.0")&"–"&TEXT(F2,"0.0"))
G3: =IF(OR(E3="",F3=""),"",IF(E3>F3,C3,IF(E3<F3,D3,"TIE"))) | H3: =IF(G3="", "", IF(G3=C3,Settings!$B$3,0)) | I3: =IF(G3="", "", IF(G3=D3,Settings!$B$3,0)) | J3: =IF(OR(E3="",H3=""),"",E3+H3) | K3: =IF(OR(F3="",I3=""),"",F3+I3) | M3: =IF(AND(A3<>"",B3<>"",C3<>"",D3<>"",E3<>"",F3<>""),1,0) | N3: =IF(M3=0,"",IF(E3>F3,1,0)) | O3: =IF(M3=0,"",IF(E3<F3,1,0)) | P3: =IF(M3=0,"",IF(E3=F3,1,0)) | Q3: =IF(M3=0,"",IF(F3>E3,1,0)) | R3: =IF(M3=0,"",IF(F3<E3,1,0)) | S3: =IF(M3=0,"",IF(F3=E3,1,0)) | T3: =IF(M3=0,"",IF(E3>F3,C3&" def. "&D3,IF(E3<F3,D3&" def. "&C3,C3&" tied "&D3))&" "&TEXT(E3,"0.0")&"–"&TEXT(F3,"0.0"))
G4: =IF(OR(E4="",F4=""),"",IF(E4>F4,C4,IF(E4<F4,D4,"TIE"))) | H4: =IF(G4="", "", IF(G4=C4,Settings!$B$3,0)) | I4: =IF(G4="", "", IF(G4=D4,Settings!$B$3,0)) | J4: =IF(OR(E4="",H4=""),"",E4+H4) | K4: =IF(OR(F4="",I4=""),"",F4+I4) | M4: =IF(AND(A4<>"",B4<>"",C4<>"",D4<>"",E4<>"",F4<>""),1,0) | N4: =IF(M4=0,"",IF(E4>F4,1,0)) | O4: =IF(M4=0,"",IF(E4<F4,1,0)) | P4: =IF(M4=0,"",IF(E4=F4,1,0)) | Q4: =IF(M4=0,"",IF(F4>E4,1,0)) | R4: =IF(M4=0,"",IF(F4<E4,1,0)) | S4: =IF(M4=0,"",IF(F4=E4,1,0)) | T4: =IF(M4=0,"",IF(E4>F4,C4&" def. "&D4,IF(E4<F4,D4&" def. "&C4,C4&" tied "&D4))&" "&TEXT(E4,"0.0")&"–"&TEXT(F4,"0.0"))
G5: =IF(OR(E5="",F5=""),"",IF(E5>F5,C5,IF(E5<F5,D5,"TIE"))) | H5: =IF(G5="", "", IF(G5=C5,Settings!$B$3,0)) | I5: =IF(G5="", "", IF(G5=D5,Settings!$B$3,0)) | J5: =IF(OR(E5="",H5=""),"",E5+H5) | K5: =IF(OR(F5="",I5=""),"",F5+I5) | M5: =IF(AND(A5<>"",B5<>"",C5<>"",D5<>"",E5<>"",F5<>""),1,0) | N5: =IF(M5=0,"",IF(E5>F5,1,0)) | O5: =IF(M5=0,"",IF(E5<F5,1,0)) | P5: =IF(M5=0,"",IF(E5=F5,1,0)) | Q5: =IF(M5=0,"",IF(F5>E5,1,0)) | R5: =IF(M5=0,"",IF(F5<E5,1,0)) | S5: =IF(M5=0,"",IF(F5=E5,1,0)) | T5: =IF(M5=0,"",IF(E5>F5,C5&" def. "&D5,IF(E5<F5,D5&" def. "&C5,C5&" tied "&D5))&" "&TEXT(E5,"0.0")&"–"&TEXT(F5,"0.0"))
G6: =IF(OR(E6="",F6=""),"",IF(E6>F6,C6,IF(E6<F6,D6,"TIE"))) | H6: =IF(G6="", "", IF(G6=C6,Settings!$B$3,0)) | I6: =IF(G6="", "", IF(G6=D6,Settings!$B$3,0)) | J6: =IF(OR(E6="",H6=""),"",E6+H6) | K6: =IF(OR(F6="",I6=""),"",F6+I6) | M6: =IF(AND(A6<>"",B6<>"",C6<>"",D6<>"",E6<>"",F6<>""),1,0) | N6: =IF(M6=0,"",IF(E6>F6,1,0)) | O6: =IF(M6=0,"",IF(E6<F6,1,0)) | P6: =IF(M6=0,"",IF(E6=F6,1,0)) | Q6: =IF(M6=0,"",IF(F6>E6,1,0)) | R6: =IF(M6=0,"",IF(F6<E6,1,0)) | S6: =IF(M6=0,"",IF(F6=E6,1,0)) | T6: =IF(M6=0,"",IF(E6>F6,C6&" def. "&D6,IF(E6<F6,D6&" def. "&C6,C6&" tied "&D6))&" "&TEXT(E6,"0.0")&"–"&TEXT(F6,"0.0"))
G7: =IF(OR(E7="",F7=""),"",IF(E7>F7,C7,IF(E7<F7,D7,"TIE"))) | H7: =IF(G7="", "", IF(G7=C7,Settings!$B$3,0)) | I7: =IF(G7="", "", IF(G7=D7,Settings!$B$3,0)) | J7: =IF(OR(E7="",H7=""),"",E7+H7) | K7: =IF(OR(F7="",I7=""),"",F7+I7) | M7: =IF(AND(A7<>"",B7<>"",C7<>"",D7<>"",E7<>"",F7<>""),1,0) | N7: =IF(M7=0,"",IF(E7>F7,1,0)) | O7: =IF(M7=0,"",IF(E7<F7,1,0)) | P7: =IF(M7=0,"",IF(E7=F7,1,0)) | Q7: =IF(M7=0,"",IF(F7>E7,1,0)) | R7: =IF(M7=0,"",IF(F7<E7,1,0)) | S7: =IF(M7=0,"",IF(F7=E7,1,0)) | T7: =IF(M7=0,"",IF(E7>F7,C7&" def. "&D7,IF(E7<F7,D7&" def. "&C7,C7&" tied "&D7))&" "&TEXT(E7,"0.0")&"–"&TEXT(F7,"0.0"))
G8: =IF(OR(E8="",F8=""),"",IF(E8>F8,C8,IF(E8<F8,D8,"TIE"))) | H8: =IF(G8="", "", IF(G8=C8,Settings!$B$3,0)) | I8: =IF(G8="", "", IF(G8=D8,Settings!$B$3,0)) | J8: =IF(OR(E8="",H8=""),"",E8+H8) | K8: =IF(OR(F8="",I8=""),"",F8+I8) | M8: =IF(AND(A8<>"",B8<>"",C8<>"",D8<>"",E8<>"",F8<>""),1,0) | N8: =IF(M8=0,"",IF(E8>F8,1,0)) | O8: =IF(M8=0,"",IF(E8<F8,1,0)) | P8: =IF(M8=0,"",IF(E8=F8,1,0)) | Q8: =IF(M8=0,"",IF(F8>E8,1,0)) | R8: =IF(M8=0,"",IF(F8<E8,1,0)) | S8: =IF(M8=0,"",IF(F8=E8,1,0)) | T8: =IF(M8=0,"",IF(E8>F8,C8&" def. "&D8,IF(E8<F8,D8&" def. "&C8,C8&" tied "&D8))&" "&TEXT(E8,"0.0")&"–"&TEXT(F8,"0.0"))
G9: =IF(OR(E9="",F9=""),"",IF(E9>F9,C9,IF(E9<F9,D9,"TIE"))) | H9: =IF(G9="", "", IF(G9=C9,Settings!$B$3,0)) | I9: =IF(G9="", "", IF(G9=D9,Settings!$B$3,0)) | J9: =IF(OR(E9="",H9=""),"",E9+H9) | K9: =IF(OR(F9="",I9=""),"",F9+I9) | M9: =IF(AND(A9<>"",B9<>"",C9<>"",D9<>"",E9<>"",F9<>""),1,0) | N9: =IF(M9=0,"",IF(E9>F9,1,0)) | O9: =IF(M9=0,"",IF(E9<F9,1,0)) | P9: =IF(M9=0,"",IF(E9=F9,1,0)) | Q9: =IF(M9=0,"",IF(F9>E9,1,0)) | R9: =IF(M9=0,"",IF(F9<E9,1,0)) | S9: =IF(M9=0,"",IF(F9=E9,1,0)) | T9: =IF(M9=0,"",IF(E9>F9,C9&" def. "&D9,IF(E9<F9,D9&" def. "&C9,C9&" tied "&D9))&" "&TEXT(E9,"0.0")&"–"&TEXT(F9,"0.0"))
G10: =IF(OR(E10="",F10=""),"",IF(E10>F10,C10,IF(E10<F10,D10,"TIE"))) | H10: =IF(G10="", "", IF(G10=C10,Settings!$B$3,0)) | I10: =IF(G10="", "", IF(G10=D10,Settings!$B$3,0)) | J10: =IF(OR(E10="",H10=""),"",E10+H10) | K10: =IF(OR(F10="",I10=""),"",F10+I10) | M10: =IF(AND(A10<>"",B10<>"",C10<>"",D10<>"",E10<>"",F10<>""),1,0) | N10: =IF(M10=0,"",IF(E10>F10,1,0)) | O10: =IF(M10=0,"",IF(E10<F10,1,0)) | P10: =IF(M10=0,"",IF(E10=F10,1,0)) | Q10: =IF(M10=0,"",IF(F10>E10,1,0)) | R10: =IF(M10=0,"",IF(F10<E10,1,0)) | S10: =IF(M10=0,"",IF(F10=E10,1,0)) | T10: =IF(M10=0,"",IF(E10>F10,C10&" def. "&D10,IF(E10<F10,D10&" def. "&C10,C10&" tied "&D10))&" "&TEXT(E10,"0.0")&"–"&TEXT(F10,"0.0"))
G11: =IF(OR(E11="",F11=""),"",IF(E11>F11,C11,IF(E11<F11,D11,"TIE"))) | H11: =IF(G11="", "", IF(G11=C11,Settings!$B$3,0)) | I11: =IF(G11="", "", IF(G11=D11,Settings!$B$3,0)) | J11: =IF(OR(E11="",H11=""),"",E11+H11) | K11: =IF(OR(F11="",I11=""),"",F11+I11) | M11: =IF(AND(A11<>"",B11<>"",C11<>"",D11<>"",E11<>"",F11<>""),1,0) | N11: =IF(M11=0,"",IF(E11>F11,1,0)) | O11: =IF(M11=0,"",IF(E11<F11,1,0)) | P11: =IF(M11=0,"",IF(E11=F11,1,0)) | Q11: =IF(M11=0,"",IF(F11>E11,1,0)) | R11: =IF(M11=0,"",IF(F11<E11,1,0)) | S11: =IF(M11=0,"",IF(F11=E11,1,0)) | T11: =IF(M11=0,"",IF(E11>F11,C11&" def. "&D11,IF(E11<F11,D11&" def. "&C11,C11&" tied "&D11))&" "&TEXT(E11,"0.0")&"–"&TEXT(F11,"0.0"))
G12: =IF(OR(E12="",F12=""),"",IF(E12>F12,C12,IF(E12<F12,D12,"TIE"))) | H12: =IF(G12="", "", IF(G12=C12,Settings!$B$3,0)) | I12: =IF(G12="", "", IF(G12=D12,Settings!$B$3,0)) | J12: =IF(OR(E12="",H12=""),"",E12+H12) | K12: =IF(OR(F12="",I12=""),"",F12+I12) | M12: =IF(AND(A12<>"",B12<>"",C12<>"",D12<>"",E12<>"",F12<>""),1,0) | N12: =IF(M12=0,"",IF(E12>F12,1,0)) | O12: =IF(M12=0,"",IF(E12<F12,1,0)) | P12: =IF(M12=0,"",IF(E12=F12,1,0)) | Q12: =IF(M12=0,"",IF(F12>E12,1,0)) | R12: =IF(M12=0,"",IF(F12<E12,1,0)) | S12: =IF(M12=0,"",IF(F12=E12,1,0)) | T12: =IF(M12=0,"",IF(E12>F12,C12&" def. "&D12,IF(E12<F12,D12&" def. "&C12,C12&" tied "&D12))&" "&TEXT(E12,"0.0")&"–"&TEXT(F12,"0.0"))
G13: =IF(OR(E13="",F13=""),"",IF(E13>F13,C13,IF(E13<F13,D13,"TIE"))) | H13: =IF(G13="", "", IF(G13=C13,Settings!$B$3,0)) | I13: =IF(G13="", "", IF(G13=D13,Settings!$B$3,0)) | J13: =IF(OR(E13="",H13=""),"",E13+H13) | K13: =IF(OR(F13="",I13=""),"",F13+I13) | M13: =IF(AND(A13<>"",B13<>"",C13<>"",D13<>"",E13<>"",F13<>""),1,0) | N13: =IF(M13=0,"",IF(E13>F13,1,0)) | O13: =IF(M13=0,"",IF(E13<F13,1,0)) | P13: =IF(M13=0,"",IF(E13=F13,1,0)) | Q13: =IF(M13=0,"",IF(F13>E13,1,0)) | R13: =IF(M13=0,"",IF(F13<E13,1,0)) | S13: =IF(M13=0,"",IF(F13=E13,1,0)) | T13: =IF(M13=0,"",IF(E13>F13,C13&" def. "&D13,IF(E13<F13,D13&" def. "&C13,C13&" tied "&D13))&" "&TEXT(E13,"0.0")&"–"&TEXT(F13,"0.0"))
... G61: =IF(OR(E61="",F61=""),"",IF(E61>F61,C61,IF(E61<F61,D61,"TIE"))) | H61: =IF(G61="", "", IF(G61=C61,Settings!$B$3,0)) | I61: =IF(G61="", "", IF(G61=D61,Settings!$B$3,0)) | J61: =IF(OR(E61="",H61=""),"",E61+H61) | K61: =IF(OR(F61="",I61=""),"",F61+I61) | M61: =IF(AND(A61<>"",B61<>"",C61<>"",D61<>"",E61<>"",F61<>""),1,0) | N61: =IF(M61=0,"",IF(E61>F61,1,0)) | O61: =IF(M61=0,"",IF(E61<F61,1,0)) | P61: =IF(M61=0,"",IF(E61=F61,1,0)) | Q61: =IF(M61=0,"",IF(F61>E61,1,0)) | R61: =IF(M61=0,"",IF(F61<E61,1,0)) | S61: =IF(M61=0,"",IF(F61=E61,1,0)) | T61: =IF(M61=0,"",IF(E61>F61,C61&" def. "&D61,IF(E61<F61,D61&" def. "&C61,C61&" tied "&D61))&" "&TEXT(E61,"0.0")&"–"&TEXT(F61,"0.0"))

Sheet Dashboard
A1: =Settings!$B$6&TEXT(TODAY(),"mmmm d, yyyy")
A2: ="("&Settings!$B$7&" / Completed Matches: "&TEXT($B$3,"0")&" of "&TEXT($D$3,"0")&")"
A3: Completed Matches | B3: =SUM(Matches!$M$2:Matches!$M$61) | C3: of | D3: =Settings!$B$5
A5: Division A Standings
A6: Rank | B6: Player | C6: Pts | D6: Matches | E6: W | F6: L | G6: T | H6: W-L-T
A7: =RANK.EQ(C7,$C$7:$C$11,0)+COUNTIFS($C$7:$C$11,C7,$E$7:$E$11,">"&E7) | B7: =Players!A2 | C7: =SUMIFS(Matches!$J$2:$J$61,Matches!$B$2:$B$61,"A",Matches!$C$2:$C$61,B7,Matches!$M$2:$M$61,1)+SUMIFS(Matches!$K$2:$K$61,Matches!$B$2:$B$61,"A",Matches!$D$2:$D$61,B7,Matches!$M$2:$M$61,1) | D7: =COUNTIFS(Matches!$B$2:$B$61,"A",Matches!$C$2:$C$61,B7,Matches!$M$2:$M$61,1)+COUNTIFS(Matches!$B$2:$B$61,"A",Matches!$D$2:$D$61,B7,Matches!$M$2:$M$61,1) | E7: =SUMIFS(Matches!$N$2:$N$61,Matches!$B$2:$B$61,"A",Matches!$C$2:$C$61,B7,Matches!$M$2:$M$61,1)+SUMIFS(Matches!$Q$2:$Q$61,Matches!$B$2:$B$61,"A",Matches!$D$2:$D$61,B7,Matches!$M$2:$M$61,1) | F7: =SUMIFS(Matches!$O$2:$O$61,Matches!$B$2:$B$61,"A",Matches!$C$2:$C$61,B7,Matches!$M$2:$M$61,1)+SUMIFS(Matches!$R$2:$R$61,Matches!$B$2:$B$61,"A",Matches!$D$2:$D$61,B7,Matches!$M$2:$M$61,1) | G7: =SUMIFS(Matches!$P$2:$P$61,Matches!$B$2:$B$61,"A",Matches!$C$2:$C$61,B7,Matches!$M$2:$M$61,1)+SUMIFS(Matches!$S$2:$S$61,Matches!$B$2:$B$61,"A",Matches!$D$2:$D$61,B7,Matches!$M$2:$M$61,1) | H7: =TEXT(E7,"0")&"-"&TEXT(F7,"0")&"-"&TEXT(G7,"0")
A8: =RANK.EQ(C8,$C$7:$C$11,0)+COUNTIFS($C$7:$C$11,C8,$E$7:$E$11,">"&E8) | B8: =Players!A3 | C8: =SUMIFS(Matches!$J$2:$J$61,Matches!$B$2:$B$61,"A",Matches!$C$2:$C$61,B8,Matches!$M$2:$M$61,1)+SUMIFS(Matches!$K$2:$K$61,Matches!$B$2:$B$61,"A",Matches!$D$2:$D$61,B8,Matches!$M$2:$M$61,1) | D8: =COUNTIFS(Matches!$B$2:$B$61,"A",Matches!$C$2:$C$61,B8,Matches!$M$2:$M$61,1)+COUNTIFS(Matches!$B$2:$B$61,"A",Matches!$D$2:$D$61,B8,Matches!$M$2:$M$61,1) | E8: =SUMIFS(Matches!$N$2:$N$61,Matches!$B$2:$B$61,"A",Matches!$C$2:$C$61,B8,Matches!$M$2:$M$61,1)+SUMIFS(Matches!$Q$2:$Q$61,Matches!$B$2:$B$61,"A",Matches!$D$2:$D$61,B8,Matches!$M$2:$M$61,1) | F8: =SUMIFS(Matches!$O$2:$O$61,Matches!$B$2:$B$61,"A",Matches!$C$2:$C$61,B8,Matches!$M$2:$M$61,1)+SUMIFS(Matches!$R$2:$R$61,Matches!$B$2:$B$61,"A",Matches!$D$2:$D$61,B8,Matches!$M$2:$M$61,1) | G8: =SUMIFS(Matches!$P$2:$P$61,Matches!$B$2:$B$61,"A",Matches!$C$2:$C$61,B8,Matches!$M$2:$M$61,1)+SUMIFS(Matches!$S$2:$S$61,Matches!$B$2:$B$61,"A",Matches!$D$2:$D$61,B8,Matches!$M$2:$M$61,1) | H8: =TEXT(E8,"0")&"-"&TEXT(F8,"0")&"-"&TEXT(G8,"0")
A9: =RANK.EQ(C9,$C$7:$C$11,0)+COUNTIFS($C$7:$C$11,C9,$E$7:$E$11,">"&E9) | B9: =Players!A4 | C9: =SUMIFS(Matches!$J$2:$J$61,Matches!$B$2:$B$61,"A",Matches!$C$2:$C$61,B9,Matches!$M$2:$M$61,1)+SUMIFS(Matches!$K$2:$K$61,Matches!$B$2:$B$61,"A",Matches!$D$2:$D$61,B9,Matches!$M$2:$M$61,1) | D9: =COUNTIFS(Matches!$B$2:$B$61,"A",Matches!$C$2:$C$61,B9,Matches!$M$2:$M$61,1)+COUNTIFS(Matches!$B$2:$B$61,"A",Matches!$D$2:$D$61,B9,Matches!$M$2:$M$61,1) | E9: =SUMIFS(Matches!$N$2:$N$61,Matches!$B$2:$B$61,"A",Matches!$C$2:$C$61,B9,Matches!$M$2:$M$61,1)+SUMIFS(Matches!$Q$2:$Q$61,Matches!$B$2:$B$61,"A",Matches!$D$2:$D$61,B9,Matches!$M$2:$M$61,1) | F9: =SUMIFS(Matches!$O$2:$O$61,Matches!$B$2:$B$61,"A",Matches!$C$2:$C$61,B9,Matches!$M$2:$M$61,1)+SUMIFS(Matches!$R$2:$R$61,Matches!$B$2:$B$61,"A",Matches!$D$2:$D$61,B9,Matches!$M$2:$M$61,1) | G9: =SUMIFS(Matches!$P$2:$P$61,Matches!$B$2:$B$61,"A",Matches!$C$2:$C$61,B9,Matches!$M$2:$M$61,1)+SUMIFS(Matches!$S$2:$S$61,Matches!$B$2:$B$61,"A",Matches!$D$2:$D$61,B9,Matches!$M$2:$M$61,1) | H9: =TEXT(E9,"0")&"-"&TEXT(F9,"0")&"-"&TEXT(G9,"0")
A10: =RANK.EQ(C10,$C$7:$C$11,0)+COUNTIFS($C$7:$C$11,C10,$E$7:$E$11,">"&E10) | B10: =Players!A5 | C10: =SUMIFS(Matches!$J$2:$J$61,Matches!$B$2:$B$61,"A",Matches!$C$2:$C$61,B10,Matches!$M$2:$M$61,1)+SUMIFS(Matches!$K$2:$K$61,Matches!$B$2:$B$61,"A",Matches!$D$2:$D$61,B10,Matches!$M$2:$M$61,1) | D10: =COUNTIFS(Matches!$B$2:$B$61,"A",Matches!$C$2:$C$61,B10,Matches!$M$2:$M$61,1)+COUNTIFS(Matches!$B$2:$B$61,"A",Matches!$D$2:$D$61,B10,Matches!$M$2:$M$61,1) | E10: =SUMIFS(Matches!$N$2:$N$61,Matches!$B$2:$B$61,"A",Matches!$C$2:$C$61,B10,Matches!$M$2:$M$61,1)+SUMIFS(Matches!$Q$2:$Q$61,Matches!$B$2:$B$61,"A",Matches!$D$2:$D$61,B10,Matches!$M$2:$M$61,1) | F10: =SUMIFS(Matches!$O$2:$O$61,Matches!$B$2:$B$61,"A",Matches!$C$2:$C$61,B10,Matches!$M$2:$M$61,1)+SUMIFS(Matches!$R$2:$R$61,Matches!$B$2:$B$61,"A",Matches!$D$2:$D$61,B10,Matches!$M$2:$M$61,1) | G10: =SUMIFS(Matches!$P$2:$P$61,Matches!$B$2:$B$61,"A",Matches!$C$2:$C$61,B10,Matches!$M$2:$M$61,1)+SUMIFS(Matches!$S$2:$S$61,Matches!$B$2:$B$61,"A",Matches!$D$2:$D$61,B10,Matches!$M$2:$M$61,1) | H10: =TEXT(E10,"0")&"-"&TEXT(F10,"0")&"-"&TEXT(G10,"0")
A11: =RANK.EQ(C11,$C$7:$C$11,0)+COUNTIFS($C$7:$C$11,C11,$E$7:$E$11,">"&E11) | B11: =Players!A6 | C11: =SUMIFS(Matches!$J$2:$J$61,Matches!$B$2:$B$61,"A",Matches!$C$2:$C$61,B11,Matches!$M$2:$M$61,1)+SUMIFS(Matches!$K$2:$K$61,Matches!$B$2:$B$61,"A",Matches!$D$2:$D$61,B11,Matches!$M$2:$M$61,1) | D11: =COUNTIFS(Matches!$B$2:$B$61,"A",Matches!$C$2:$C$61,B11,Matches!$M$2:$M$61,1)+COUNTIFS(Matches!$B$2:$B$61,"A",Matches!$D$2:$D$61,B11,Matches!$M$2:$M$61,1) | E11: =SUMIFS(Matches!$N$2:$N$61,Matches!$B$2:$B$61,"A",Matches!$C$2:$C$61,B11,Matches!$M$2:$M$61,1)+SUMIFS(Matches!$Q$2:$Q$61,Matches!$B$2:$B$61,"A",Matches!$D$2:$D$61,B11,Matches!$M$2:$M$61,1) | F11: =SUMIFS(Matches!$O$2:$O$61,Matches!$B$2:$B$61,"A",Matches!$C$2:$C$61,B11,Matches!$M$2:$M$61,1)+SUMIFS(Matches!$R$2:$R$61,Matches!$B$2:$B$61,"A",Matches!$D$2:$D$61,B11,Matches!$M$2:$M$61,1) | G11: =SUMIFS(Matches!$P$2:$P$61,Matches!$B$2:$B$61,"A",Matches!$C$2:$C$61,B11,Matches!$M$2:$M$61,1)+SUMIFS(Matches!$S$2:$S$61,Matches!$B$2:$B$61,"A",Matches!$D$2:$D$61,B11,Matches!$M$2:$M$61,1) | H11: =TEXT(E11,"0")&"-"&TEXT(F11,"0")&"-"&TEXT(G11,"0")
A13: Division B Standings
A14: Rank | B14: Player | C14: Pts | D14: Matches | E14: W | F14: L | G14: T | H14: W-L-T
A15: =RANK.EQ(C15,$C$15:$C$19,0)+COUNTIFS($C$15:$C$19,C15,$E$15:$E$19,">"&E15) | B15: =Players!A7 | C15: =SUMIFS(Matches!$J$2:$J$61,Matches!$B$2:$B$61,"B",Matches!$C$2:$C$61,B15,Matches!$M$2:$M$61,1)+SUMIFS(Matches!$K$2:$K$61,Matches!$B$2:$B$61,"B",Matches!$D$2:$D$61,B15,Matches!$M$2:$M$61,1) | D15: =COUNTIFS(Matches!$B$2:$B$61,"B",Matches!$C$2:$C$61,B15,Matches!$M$2:$M$61,1)+COUNTIFS(Matches!$B$2:$B$61,"B",Matches!$D$2:$D$61,B15,Matches!$M$2:$M$61,1) | E15: =SUMIFS(Matches!$N$2:$N$61,Matches!$B$2:$B$61,"B",Matches!$C$2:$C$61,B15,Matches!$M$2:$M$61,1)+SUMIFS(Matches!$Q$2:$Q$61,Matches!$B$2:$B$61,"B",Matches!$D$2:$D$61,B15,Matches!$M$2:$M$61,1) | F15: =SUMIFS(Matches!$O$2:$O$61,Matches!$B$2:$B$61,"B",Matches!$C$2:$C$61,B15,Matches!$M$2:$M$61,1)+SUMIFS(Matches!$R$2:$R$61,Matches!$B$2:$B$61,"B",Matches!$D$2:$D$61,B15,Matches!$M$2:$M$61,1) | G15: =SUMIFS(Matches!$P$2:$P$61,Matches!$B$2:$B$61,"B",Matches!$C$2:$C$61,B15,Matches!$M$2:$M$61,1)+SUMIFS(Matches!$S$2:$S$61,Matches!$B$2:$B$61,"B",Matches!$D$2:$D$61,B15,Matches!$M$2:$M$61,1) | H15: =TEXT(E15,"0")&"-"&TEXT(F15,"0")&"-"&TEXT(G15,"0")
A16: =RANK.EQ(C16,$C$15:$C$19,0)+COUNTIFS($C$15:$C$19,C16,$E$15:$E$19,">"&E16) | B16: =Players!A8 | C16: =SUMIFS(Matches!$J$2:$J$61,Matches!$B$2:$B$61,"B",Matches!$C$2:$C$61,B16,Matches!$M$2:$M$61,1)+SUMIFS(Matches!$K$2:$K$61,Matches!$B$2:$B$61,"B",Matches!$D$2:$D$61,B16,Matches!$M$2:$M$61,1) | D16: =COUNTIFS(Matches!$B$2:$B$61,"B",Matches!$C$2:$C$61,B16,Matches!$M$2:$M$61,1)+COUNTIFS(Matches!$B$2:$B$61,"B",Matches!$D$2:$D$61,B16,Matches!$M$2:$M$61,1) | E16: =SUMIFS(Matches!$N$2:$N$61,Matches!$B$2:$B$61,"B",Matches!$C$2:$C$61,B16,Matches!$M$2:$M$61,1)+SUMIFS(Matches!$Q$2:$Q$61,Matches!$B$2:$B$61,"B",Matches!$D$2:$D$61,B16,Matches!$M$2:$M$61,1) | F16: =SUMIFS(Matches!$O$2:$O$61,Matches!$B$2:$B$61,"B",Matches!$C$2:$C$61,B16,Matches!$M$2:$M$61,1)+SUMIFS(Matches!$R$2:$R$61,Matches!$B$2:$B$61,"B",Matches!$D$2:$D$61,B16,Matches!$M$2:$M$61,1) | G16: =SUMIFS(Matches!$P$2:$P$61,Matches!$B$2:$B$61,"B",Matches!$C$2:$C$61,B16,Matches!$M$2:$M$61,1)+SUMIFS(Matches!$S$2:$S$61,Matches!$B$2:$B$61,"B",Matches!$D$2:$D$61,B16,Matches!$M$2:$M$61,1) | H16: =TEXT(E16,"0")&"-"&TEXT(F16,"0")&"-"&TEXT(G16,"0")
A17: =RANK.EQ(C17,$C$15:$C$19,0)+COUNTIFS($C$15:$C$19,C17,$E$15:$E$19,">"&E17) | B17: =Players!A9 | C17: =SUMIFS(Matches!$J$2:$J$61,Matches!$B$2:$B$61,"B",Matches!$C$2:$C$61,B17,Matches!$M$2:$M$61,1)+SUMIFS(Matches!$K$2:$K$61,Matches!$B$2:$B$61,"B",Matches!$D$2:$D$61,B17,Matches!$M$2:$M$61,1) | D17: =COUNTIFS(Matches!$B$2:$B$61,"B",Matches!$C$2:$C$61,B17,Matches!$M$2:$M$61,1)+COUNTIFS(Matches!$B$2:$B$61,"B",Matches!$D$2:$D$61,B17,Matches!$M$2:$M$61,1) | E17: =SUMIFS(Matches!$N$2:$N$61,Matches!$B$2:$B$61,"B",Matches!$C$2:$C$61,B17,Matches!$M$2:$M$61,1)+SUMIFS(Matches!$Q$2:$Q$61,Matches!$B$2:$B$61,"B",Matches!$D$2:$D$61,B17,Matches!$M$2:$M$61,1) | F17: =SUMIFS(Matches!$O$2:$O$61,Matches!$B$2:$B$61,"B",Matches!$C$2:$C$61,B17,Matches!$M$2:$M$61,1)+SUMIFS(Matches!$R$2:$R$61,Matches!$B$2:$B$61,"B",Matches!$D$2:$D$61,B17,Matches!$M$2:$M$61,1) | G17: =SUMIFS(Matches!$P$2:$P$61,Matches!$B$2:$B$61,"B",Matches!$C$2:$C$61,B17,Matches!$M$2:$M$61,1)+SUMIFS(Matches!$S$2:$S$61,Matches!$B$2:$B$61,"B",Matches!$D$2:$D$61,B17,Matches!$M$2:$M$61,1) | H17: =TEXT(E17,"0")&"-"&TEXT(F17,"0")&"-"&TEXT(G17,"0")
A18: =RANK.EQ(C18,$C$15:$C$19,0)+COUNTIFS($C$15:$C$19,C18,$E$15:$E$19,">"&E18) | B18: =Players!A10 | C18: =SUMIFS(Matches!$J$2:$J$61,Matches!$B$2:$B$61,"B",Matches!$C$2:$C$61,B18,Matches!$M$2:$M$61,1)+SUMIFS(Matches!$K$2:$K$61,Matches!$B$2:$B$61,"B",Matches!$D$2:$D$61,B18,Matches!$M$2:$M$61,1) | D18: =COUNTIFS(Matches!$B$2:$B$61,"B",Matches!$C$2:$C$61,B18,Matches!$M$2:$M$61,1)+COUNTIFS(Matches!$B$2:$B$61,"B",Matches!$D$2:$D$61,B18,Matches!$M$2:$M$61,1) | E18: =SUMIFS(Matches!$N$2:$N$61,Matches!$B$2:$B$61,"B",Matches!$C$2:$C$61,B18,Matches!$M$2:$M$61,1)+SUMIFS(Matches!$Q$2:$Q$61,Matches!$B$2:$B$61,"B",Matches!$D$2:$D$61,B18,Matches!$M$2:$M$61,1) | F18: =SUMIFS(Matches!$O$2:$O$61,Matches!$B$2:$B$61,"B",Matches!$C$2:$C$61,B18,Matches!$M$2:$M$61,1)+SUMIFS(Matches!$R$2:$R$61,Matches!$B$2:$B$61,"B",Matches!$D$2:$D$61,B18,Matches!$M$2:$M$61,1) | G18: =SUMIFS(Matches!$P$2:$P$61,Matches!$B$2:$B$61,"B",Matches!$C$2:$C$61,B18,Matches!$M$2:$M$61,1)+SUMIFS(Matches!$S$2:$S$61,Matches!$B$2:$B$61,"B",Matches!$D$2:$D$61,B18,Matches!$M$2:$M$61,1) | H18: =TEXT(E18,"0")&"-"&TEXT(F18,"0")&"-"&TEXT(G18,"0")
A19: =RANK.EQ(C19,$C$15:$C$19,0)+COUNTIFS($C$15:$C$19,C19,$E$15:$E$19,">"&E19) | B19: =Players!A11 | C19: =SUMIFS(Matches!$J$2:$J$61,Matches!$B$2:$B$61,"B",Matches!$C$2:$C$61,B19,Matches!$M$2:$M$61,1)+SUMIFS(Matches!$K$2:$K$61,Matches!$B$2:$B$61,"B",Matches!$D$2:$D$61,B19,Matches!$M$2:$M$61,1) | D19: =COUNTIFS(Matches!$B$2:$B$61,"B",Matches!$C$2:$C$61,B19,Matches!$M$2:$M$61,1)+COUNTIFS(Matches!$B$2:$B$61,"B",Matches!$D$2:$D$61,B19,Matches!$M$2:$M$61,1) | E19: =SUMIFS(Matches!$N$2:$N$61,Matches!$B$2:$B$61,"B",Matches!$C$2:$C$61,B19,Matches!$M$2:$M$61,1)+SUMIFS(Matches!$Q$2:$Q$61,Matches!$B$2:$B$61,"B",Matches!$D$2:$D$61,B19,Matches!$M$2:$M$61,1) | F19: =SUMIFS(Matches!$O$2:$O$61,Matches!$B$2:$B$61,"B",Matches!$C$2:$C$61,B19,Matches!$M$2:$M$61,1)+SUMIFS(Matches!$R$2:$R$61,Matches!$B$2:$B$61,"B",Matches!$D$2:$D$61,B19,Matches!$M$2:$M$61,1) | G19: =SUMIFS(Matches!$P$2:$P$61,Matches!$B$2:$B$61,"B",Matches!$C$2:$C$61,B19,Matches!$M$2:$M$61,1)+SUMIFS(Matches!$S$2:$S$61,Matches!$B$2:$B$61,"B",Matches!$D$2:$D$61,B19,Matches!$M$2:$M$61,1) | H19: =TEXT(E19,"0")&"-"&TEXT(F19,"0")&"-"&TEXT(G19,"0")
A21: Match Results (most recent first)
A22: Division A
A23: Date | B23: Result | C23: Notes
A24: =LET(d,Matches!$A$2:$A$61,div,Matches!$B$2:$B$61,res,Matches!$T$2:$T$61,notes,Matches!$L$2:$L$61,comp,Matches!$M$2:$M$61,mask,(div="A")*(comp=1),sorted,SORTBY(FILTER(HSTACK(d,res,notes),mask),1,-1),TAKE(sorted,10))
A30: Division B
A31: Date | B31: Result | C31: Notes
A32: =LET(d,Matches!$A$2:$A$61,div,Matches!$B$2:$B$61,res,Matches!$T$2:$T$61,notes,Matches!$L$2:$L$61,comp,Matches!$M$2:$M$61,mask,(div="B")*(comp=1),sorted,SORTBY(FILTER(HSTACK(d,res,notes),mask),1,-1),TAKE(sorted,10))
A40: Playoffs
A41: Date | B41: Result | C41: Notes
A42: =LET(d,Matches!$A$2:$A$61,div,Matches!$B$2:$B$61,res,Matches!$G$2:$G$61,notes,Matches!$L$2:$L$61,done,Matches!$M$2:$M$61,mask,(div="PO")*(done=1),filt,FILTER(CHOOSE({1,2,3},d,res,notes),mask,""),SORT(filt,1,-1))

Sheet Update Text
A1: Copy/Paste Update (auto-generated)
A3: Output:
A4: Division A Standings | C4: Division B Standings
A5: =TEXT(A7,"0")&". "&Dashboard!B7&" – "&TEXT(Dashboard!C7,"0.0")&" pts ("&TEXT(Dashboard!D7,"0")&" matches | "&Dashboard!H7&")" | C5: =TEXT(A15,"0")&". "&Dashboard!B15&" – "&TEXT(Dashboard!C15,"0.0")&" pts ("&TEXT(Dashboard!D15,"0")&" matches | "&Dashboard!H15&")"
A6: =TEXT(A8,"0")&". "&Dashboard!B8&" – "&TEXT(Dashboard!C8,"0.0")&" pts ("&TEXT(Dashboard!D8,"0")&" matches | "&Dashboard!H8&")" | C6: =TEXT(A16,"0")&". "&Dashboard!B16&" – "&TEXT(Dashboard!C16,"0.0")&" pts ("&TEXT(Dashboard!D16,"0")&" matches | "&Dashboard!H16&")"
A7: =TEXT(A9,"0")&". "&Dashboard!B9&" – "&TEXT(Dashboard!C9,"0.0")&" pts ("&TEXT(Dashboard!D9,"0")&" matches | "&Dashboard!H9&")" | C7: =TEXT(A17,"0")&". "&Dashboard!B17&" – "&TEXT(Dashboard!C17,"0.0")&" pts ("&TEXT(Dashboard!D17,"0")&" matches | "&Dashboard!H17&")"
A8: =TEXT(A10,"0")&". "&Dashboard!B10&" – "&TEXT(Dashboard!C10,"0.0")&" pts ("&TEXT(Dashboard!D10,"0")&" matches | "&Dashboard!H10&")" | C8: =TEXT(A18,"0")&". "&Dashboard!B18&" – "&TEXT(Dashboard!C18,"0.0")&" pts ("&TEXT(Dashboard!D18,"0")&" matches | "&Dashboard!H18&")"
A9: =TEXT(A11,"0")&". "&Dashboard!B11&" – "&TEXT(Dashboard!C11,"0.0")&" pts ("&TEXT(Dashboard!D11,"0")&" matches | "&Dashboard!H11&")" | C9: =TEXT(A19,"0")&". "&Dashboard!B19&" – "&TEXT(Dashboard!C19,"0.0")&" pts ("&TEXT(Dashboard!D19,"0")&" matches | "&Dashboard!H19&")"
A10: Division B Standings
A11: =TEXT(1,"0")&". "&Dashboard!B15&" – "&TEXT(Dashboard!C15,"0.0")&" pts ("&TEXT(Dashboard!D15,"0")&" matches | "&Dashboard!H15&")"
A12: =TEXT(2,"0")&". "&Dashboard!B16&" – "&TEXT(Dashboard!C16,"0.0")&" pts ("&TEXT(Dashboard!D16,"0")&" matches | "&Dashboard!H16&")"
A13: =TEXTJOIN(CHAR(10),TRUE,Dashboard!A1,Dashboard!A2,"","Division A Standings",A5:A9,"",A10,A11:A15,"",A18,A20:A30,"",A34,A35:A44,"",A48,A49:A53)
A14: =TEXT(4,"0")&". "&Dashboard!B18&" – "&TEXT(Dashboard!C18,"0.0")&" pts ("&TEXT(Dashboard!D18,"0")&" matches | "&Dashboard!H18&")"
A15: =TEXT(5,"0")&". "&Dashboard!B19&" – "&TEXT(Dashboard!C19,"0.0")&" pts ("&TEXT(Dashboard!D19,"0")&" matches | "&Dashboard!H19&")"
A18: Match Results (most recent first)
A20: Division A
A21: =IF(Dashboard!A24="","",TEXT(Dashboard!A24,"m/d")&" – "&Dashboard!B24&IF(Dashboard!C24<>""," ("&Dashboard!C24&")",""))
A22: =IF(Dashboard!A25="","",TEXT(Dashboard!A25,"m/d")&" – "&Dashboard!B25&IF(Dashboard!C25<>""," ("&Dashboard!C25&")",""))
A23: =IF(Dashboard!A26="","",TEXT(Dashboard!A26,"m/d")&" – "&Dashboard!B26&IF(Dashboard!C26<>""," ("&Dashboard!C26&")",""))
A24: =IF(Dashboard!A27="","",TEXT(Dashboard!A27,"m/d")&" – "&Dashboard!B27&IF(Dashboard!C27<>""," ("&Dashboard!C27&")",""))
A25: =IF(Dashboard!A28="","",TEXT(Dashboard!A28,"m/d")&" – "&Dashboard!B28&IF(Dashboard!C28<>""," ("&Dashboard!C28&")",""))
A26: =IF(Dashboard!A29="","",TEXT(Dashboard!A29,"m/d")&" – "&Dashboard!B29&IF(Dashboard!C29<>""," ("&Dashboard!C29&")",""))
A27: =IF(Dashboard!A30="","",TEXT(Dashboard!A30,"m/d")&" – "&Dashboard!B30&IF(Dashboard!C30<>""," ("&Dashboard!C30&")",""))
A28: =IF(Dashboard!A31="","",TEXT(Dashboard!A31,"m/d")&" – "&Dashboard!B31&IF(Dashboard!C31<>""," ("&Dashboard!C31&")",""))
A29: =IF(Dashboard!A32="","",TEXT(Dashboard!A32,"m/d")&" – "&Dashboard!B32&IF(Dashboard!C32<>""," ("&Dashboard!C32&")",""))
A30: =IF(Dashboard!A33="","",TEXT(Dashboard!A33,"m/d")&" – "&Dashboard!B33&IF(Dashboard!C33<>""," ("&Dashboard!C33&")",""))
A34: Division B
A35: =IF(Dashboard!A32="","",TEXT(Dashboard!A32,"m/d")&" – "&Dashboard!B32&IF(Dashboard!C32<>""," ("&Dashboard!C32&")",""))
A36: =IF(Dashboard!A33="","",TEXT(Dashboard!A33,"m/d")&" – "&Dashboard!B33&IF(Dashboard!C33<>""," ("&Dashboard!C33&")",""))
A37: =IF(Dashboard!A34="","",TEXT(Dashboard!A34,"m/d")&" – "&Dashboard!B34&IF(Dashboard!C34<>""," ("&Dashboard!C34&")",""))
A38: =IF(Dashboard!A35="","",TEXT(Dashboard!A35,"m/d")&" – "&Dashboard!B35&IF(Dashboard!C35<>""," ("&Dashboard!C35&")",""))
A39: =IF(Dashboard!A36="","",TEXT(Dashboard!A36,"m/d")&" – "&Dashboard!B36&IF(Dashboard!C36<>""," ("&Dashboard!C36&")",""))
A40: =IF(Dashboard!A37="","",TEXT(Dashboard!A37,"m/d")&" – "&Dashboard!B37&IF(Dashboard!C37<>""," ("&Dashboard!C37&")",""))
A41: =IF(Dashboard!A38="","",TEXT(Dashboard!A38,"m/d")&" – "&Dashboard!B38&IF(Dashboard!C38<>""," ("&Dashboard!C38&")",""))
A42: =IF(Dashboard!A39="","",TEXT(Dashboard!A39,"m/d")&" – "&Dashboard!B39&IF(Dashboard!C39<>""," ("&Dashboard!C39&")",""))
A43: =IF(Dashboard!A40="","",TEXT(Dashboard!A40,"m/d")&" – "&Dashboard!B40&IF(Dashboard!C40<>""," ("&Dashboard!C40&")",""))
A44: =IF(Dashboard!A41="","",TEXT(Dashboard!A41,"m/d")&" – "&Dashboard!B41&IF(Dashboard!C41<>""," ("&Dashboard!C41&")",""))
A48: Playoffs
A49: =IF(Dashboard!A42="","",TEXT(Dashboard!A42,"m/d")&" – "&Dashboard!B42&IF(Dashboard!C42<>""," ("&Dashboard!C42&")",""))
A50: =IF(Dashboard!A43="","",TEXT(Dashboard!A43,"m/d")&" – "&Dashboard!B43&IF(Dashboard!C43<>""," ("&Dashboard!C43&")",""))
...
